<?xml version="1.0" ?>
<sdf version="1.8">
    <model name='vehicle'>
      <link name='chassis'>
        <pose>0 0 0.284363 0 0 0</pose>
        <inertial>
          <mass>1.14395</mass>
          <inertia>
            <ixx>0.126164</ixx>
            <ixy>0</ixy>
            <ixz>0</ixz>
            <iyy>0.416519</iyy>
            <iyz>0</iyz>
            <izz>0.481014</izz>
          </inertia>
        </inertial>
        <visual name='visual_chassis'>
          <geometry>
            <box>
              <size>2.01142 1 0.568726</size>
            </box>
          </geometry>
          <material>
            <ambient>0.5 0.5 1.0 1</ambient>
            <diffuse>0.5 0.5 1.0 1</diffuse>
            <specular>0.0 0.0 1.0 1</specular>
          </material>
        </visual>

	<sensor name='scan' type='gpu_lidar'>
	  <topic>/scan</topic>
	  <pose>0 0 0.60 0 0 0</pose>
	  <update_rate>15</update_rate>
          <lidar>
	        <horizontal>
		      <samples>360</samples>
     		      <resolution>1</resolution>
     		      <min_angle>-3.14159</min_angle>
     		      <max_angle>3.14159</max_angle>
   		 </horizontal>
		 <range>
		   <min>0.1</min>
		   <max>15.0</max>
		   <resolution>0.01</resolution>
		 </range>
          </lidar>
	</sensor>

        <collision name='collision_chassis'>
          <geometry>
            <box>
              <size>2.01142 1 0.568726</size>
            </box>
          </geometry>
        </collision>
      </link>

      <link name='left_wheel'>
        <pose>0 0.625 0.3 0 0 0</pose>
        <inertial>
          <mass>2</mass>
          <inertia>
            <ixx>0.145833</ixx>
            <ixy>0</ixy>
            <ixz>0</ixz>
            <iyy>0.145833</iyy>
            <iyz>0</iyz>
            <izz>0.125</izz>
          </inertia>
        </inertial>
        <visual name='visual_left_wheel'>
          <geometry> <!---->
            <cylinder>  
              <radius>0.3</radius>
              <length>0.08</length>
            </cylinder>
          </geometry>
          <pose>0 0 0 1.5708 0 0</pose>
          <material>
            <ambient>0.2 0.2 0.2 1</ambient>
            <diffuse>0.2 0.2 0.2 1</diffuse>
            <specular>0.2 0.2 0.2 1</specular>
          </material>
        </visual>
        <collision name='collision_left_wheel'>
          <geometry>
            <cylinder>  
              <radius>0.3</radius>
              <length>0.08</length>
            </cylinder>
          </geometry>
          <pose>0 0 0 1.5708 0 0</pose>
          <surface>
            <friction>
              <ode>
                <mu>1.0</mu>
                <mu2>1.0</mu2>
              </ode>
            </friction>
          </surface>
        </collision>
      </link>

      <link name='right_wheel'>
        <pose>0 -0.625 0.3 0 0 0</pose>
        <inertial>
          <mass>2</mass>
          <inertia>
            <ixx>0.145833</ixx>
            <ixy>0</ixy>
            <ixz>0</ixz>
            <iyy>0.145833</iyy>
            <iyz>0</iyz>
            <izz>0.125</izz>
          </inertia>
        </inertial>
        <visual name='visual_right_wheel'>
          <geometry>
            <cylinder>  
              <radius>0.3</radius>
              <length>0.08</length>
            </cylinder>
          </geometry>
          <pose>0 0 0 1.5708 0 0</pose>
          <material>
            <ambient>0.2 0.2 0.2 1</ambient>
            <diffuse>0.2 0.2 0.2 1</diffuse>
            <specular>0.2 0.2 0.2 1</specular>
          </material>
        </visual>
        <collision name='collision_right_wheel'>
          <geometry>
            <cylinder>  
              <radius>0.3</radius>
              <length>0.08</length>
            </cylinder>
          </geometry>
          <pose>0 0 0 1.5708 0 0</pose>
          <surface>
            <friction>
              <ode>
                <mu>1.0</mu>
                <mu2>1.0</mu2>
              </ode>
            </friction>
          </surface>
        </collision>
      </link>

      <link name='caster'>
        <pose>-0.5 0 0.2 0 0 0</pose>
        <inertial>
          <mass>1</mass>
          <inertia>
            <ixx>0.1</ixx>
            <ixy>0</ixy>
            <ixz>0</ixz>
            <iyy>0.1</iyy>
            <iyz>0</iyz>
            <izz>0.1</izz>
          </inertia>
        </inertial>
        <visual name='visual_caster'>
          <geometry>
            <sphere>
              <radius>0.2</radius>
            </sphere>
          </geometry>
          <material>
            <ambient>0.2 0.2 0.2 1</ambient>
            <diffuse>0.2 0.2 0.2 1</diffuse>
            <specular>0.2 0.2 0.2 1</specular>
          </material>
        </visual>
        <collision name='collision_caster'>
          <geometry>
            <sphere>
              <radius>0.2</radius>
            </sphere>
          </geometry>
        </collision>
      </link>

      <joint name='left_wheel_joint' type='revolute'>
        <parent>chassis</parent>
        <child>left_wheel</child>
        <axis>
          <xyz>0 1 0</xyz>
          <limit>
            <lower>-1e16</lower>
            <upper>1e16</upper>
          </limit>
          <dynamics><damping>0.05</damping></dynamics>
        </axis>
      </joint>

      <joint name='right_wheel_joint' type='revolute'>
        <parent>chassis</parent>
        <child>right_wheel</child>
        <axis>
          <xyz>0 1 0</xyz>
          <limit>
            <lower>-1e16</lower>
            <upper>1e16</upper>
          </limit>
          <dynamics><damping>0.05</damping></dynamics>
        </axis>
      </joint>

      <joint name='caster_wheel' type='ball'>
        <parent>chassis</parent>
        <child>caster</child>
      </joint>

      <plugin
        filename="ignition-gazebo-diff-drive-system"
        name="ignition::gazebo::systems::DiffDrive">
        <left_joint>left_wheel_joint</left_joint>
        <right_joint>right_wheel_joint</right_joint>
        <wheel_separation>1.25</wheel_separation>
        <wheel_radius>0.3</wheel_radius>
        <odom_publish_frequency>10</odom_publish_frequency>
        <max_linear_acceleration>3.0</max_linear_acceleration>
        <min_linear_acceleration>-3.0</min_linear_acceleration>
        <max_angular_acceleration>4.0</max_angular_acceleration>
        <min_angular_acceleration>-4.0</min_angular_acceleration>
        <max_linear_velocity>1.5</max_linear_velocity>
        <min_linear_velocity>-1.5</min_linear_velocity>
        <max_angular_velocity>2.5</max_angular_velocity>
        <min_angular_velocity>-2.5</min_angular_velocity>
      </plugin>

    </model>
</sdf>
